Workbook

Sheet Main
A1: RestaurantID | B1: RestaurantName | C1: CountryCode | D1: City | E1: Locality | F1: Longitude | G1: Latitude | H1: Cuisines | I1: Currency | J1: Has_Table_booking | K1: Has_Online_delivery | L1: Is_delivering_now | M1: Switch_to_order_menu | N1: Price_range | O1: Votes | P1: Average_Cost_for_two | Q1: Rating | R1: Year Opening | S1: Month Opening | T1: Day Opening | U1: Date | V1: Avg_Cost_USD | W1: Price_Bucket
A2: 18435314 | B2: Punjabi's Veg Grill | C2: 1 | D2: New Delhi | E2: Geeta Colony | F2: 77.276769 | G2: 28.650775 | H2: North Indian | I2: Indian Rupees(Rs.) | J2: No | K2: No | L2: No | M2: No | N2: 1 | O2: 0 | P2: 300 | Q2: 1 | R2: 2013 | S2: 9 | T2: 21 | U2: 41538 | V2: =Main[[#This Row],[Average_Cost_for_two]] * VLOOKUP(Main[[#This Row],[Currency]],'Currency'!A:B,2,FALSE) -> 3.6 | W2: =IF(Main[[#This Row],[Avg_Cost_USD]]<10,"Low", IF(Main[[#This Row],[Avg_Cost_USD]]<=30,"Medium","High")) -> Low
A3: 18378015 | B3: Tasty Tandoor | C3: 1 | D3: New Delhi | E3: Geeta Colony | F3: 77.275052 | G3: 28.658216 | H3: North Indian | I3: Indian Rupees(Rs.) | J3: No | K3: No | L3: No | M3: No | N3: 1 | O3: 0 | P3: 200 | Q3: 1 | R3: 2016 | S3: 9 | T3: 10 | U3: 42623 | V3: =Main[[#This Row],[Average_Cost_for_two]] * VLOOKUP(Main[[#This Row],[Currency]],'Currency'!A:B,2,FALSE) -> 2.4 | W3: =IF(Main[[#This Row],[Avg_Cost_USD]]<10,"Low", IF(Main[[#This Row],[Avg_Cost_USD]]<=30,"Medium","High")) -> Low
A4: 18424905 | B4: Taste of Spice | C4: 1 | D4: New Delhi | E4: Lajpat Nagar 1 | F4: 77.241312 | G4: 28.578311 | H4: North Indian | I4: Indian Rupees(Rs.) | J4: No | K4: Yes | L4: No | M4: No | N4: 1 | O4: 0 | P4: 400 | Q4: 1 | R4: 2018 | S4: 9 | T4: 25 | U4: 43368 | V4: =Main[[#This Row],[Average_Cost_for_two]] * VLOOKUP(Main[[#This Row],[Currency]],'Currency'!A:B,2,FALSE) -> 4.8 | W4: =IF(Main[[#This Row],[Avg_Cost_USD]]<10,"Low", IF(Main[[#This Row],[Avg_Cost_USD]]<=30,"Medium","High")) -> Low
A5: 18180072 | B5: Kolcata Bengali Dhaba | C5: 1 | D5: New Delhi | E5: Mahipalpur | F5: 77.123932 | G5: 28.543587 | H5: North Indian | I5: Indian Rupees(Rs.) | J5: No | K5: No | L5: No | M5: No | N5: 1 | O5: 0 | P5: 100 | Q5: 1 | R5: 2018 | S5: 9 | T5: 6 | U5: 43349 | V5: =Main[[#This Row],[Average_Cost_for_two]] * VLOOKUP(Main[[#This Row],[Currency]],'Currency'!A:B,2,FALSE) -> 1.2 | W5: =IF(Main[[#This Row],[Avg_Cost_USD]]<10,"Low", IF(Main[[#This Row],[Avg_Cost_USD]]<=30,"Medium","High")) -> Low
A6: 18415377 | B6: Sunil Punjabi Dhaba | C6: 1 | D6: New Delhi | E6: Mahipalpur | F6: 77.129706 | G6: 28.541369 | H6: North Indian | I6: Indian Rupees(Rs.) | J6: No | K6: No | L6: No | M6: No | N6: 1 | O6: 0 | P6: 150 | Q6: 1 | R6: 2013 | S6: 9 | T6: 17 | U6: 41534 | V6: =Main[[#This Row],[Average_Cost_for_two]] * VLOOKUP(Main[[#This Row],[Currency]],'Currency'!A:B,2,FALSE) -> 1.8 | W6: =IF(Main[[#This Row],[Avg_Cost_USD]]<10,"Low", IF(Main[[#This Row],[Avg_Cost_USD]]<=30,"Medium","High")) -> Low
A7: 18421485 | B7: Bikaner Restaurant | C7: 1 | D7: New Delhi | E7: Mukherjee Nagar | F7: 77.208135 | G7: 28.699566 | H7: North Indian | I7: Indian Rupees(Rs.) | J7: No | K7: No | L7: No | M7: No | N7: 1 | O7: 0 | P7: 100 | Q7: 1 | R7: 2018 | S7: 9 | T7: 3 | U7: 43346 | V7: =Main[[#This Row],[Average_Cost_for_two]] * VLOOKUP(Main[[#This Row],[Currency]],'Currency'!A:B,2,FALSE) -> 1.2 | W7: =IF(Main[[#This Row],[Avg_Cost_USD]]<10,"Low", IF(Main[[#This Row],[Avg_Cost_USD]]<=30,"Medium","High")) -> Low
A8: 312413 | B8: Just In | C8: 1 | D8: New Delhi | E8: Mukherjee Nagar | F8: 77.219094 | G8: 28.70948 | H8: North Indian | I8: Indian Rupees(Rs.) | J8: No | K8: No | L8: No | M8: No | N8: 1 | O8: 0 | P8: 200 | Q8: 1 | R8: 2011 | S8: 9 | T8: 16 | U8: 40802 | V8: =Main[[#This Row],[Average_Cost_for_two]] * VLOOKUP(Main[[#This Row],[Currency]],'Currency'!A:B,2,FALSE) -> 2.4 | W8: =IF(Main[[#This Row],[Avg_Cost_USD]]<10,"Low", IF(Main[[#This Row],[Avg_Cost_USD]]<=30,"Medium","High")) -> Low
A9: 303497 | B9: Shri Shyam Ji Shudh Shakahari Bhojnalaya | C9: 1 | D9: New Delhi | E9: Najafgarh | F9: 76.974892 | G9: 28.611254 | H9: North Indian | I9: Indian Rupees(Rs.) | J9: No | K9: No | L9: No | M9: No | N9: 1 | O9: 0 | P9: 150 | Q9: 1 | R9: 2014 | S9: 9 | T9: 21 | U9: 41903 | V9: =Main[[#This Row],[Average_Cost_for_two]] * VLOOKUP(Main[[#This Row],[Currency]],'Currency'!A:B,2,FALSE) -> 1.8 | W9: =IF(Main[[#This Row],[Avg_Cost_USD]]<10,"Low", IF(Main[[#This Row],[Avg_Cost_USD]]<=30,"Medium","High")) -> Low
A10: 18354644 | B10: Shree Bhojnalaya | C10: 1 | D10: New Delhi | E10: New Friends Colony | F10: 77.272762 | G10: 28.560771 | H10: North Indian | I10: Indian Rupees(Rs.) | J10: No | K10: No | L10: No | M10: No | N10: 1 | O10: 0 | P10: 100 | Q10: 1 | R10: 2012 | S10: 9 | T10: 9 | U10: 41161 | V10: =Main[[#This Row],[Average_Cost_for_two]] * VLOOKUP(Main[[#This Row],[Currency]],'Currency'!A:B,2,FALSE) -> 1.2 | W10: =IF(Main[[#This Row],[Avg_Cost_USD]]<10,"Low", IF(Main[[#This Row],[Avg_Cost_USD]]<=30,"Medium","High")) -> Low
A11: 18366001 | B11: Baba Ka Dhaba | C11: 1 | D11: New Delhi | E11: Palam | F11: 77.09028 | G11: 28.582898 | H11: North Indian | I11: Indian Rupees(Rs.) | J11: No | K11: No | L11: No | M11: No | N11: 1 | O11: 0 | P11: 200 | Q11: 1 | R11: 2014 | S11: 9 | T11: 21 | U11: 41903 | V11: =Main[[#This Row],[Average_Cost_for_two]] * VLOOKUP(Main[[#This Row],[Currency]],'Currency'!A:B,2,FALSE) -> 2.4 | W11: =IF(Main[[#This Row],[Avg_Cost_USD]]<10,"Low", IF(Main[[#This Row],[Avg_Cost_USD]]<=30,"Medium","High")) -> Low
A12: 18486845 | B12: Kaka Da Dhaba | C12: 1 | D12: New Delhi | E12: R K Puram | F12: 77.174118 | G12: 28.577193 | H12: North Indian | I12: Indian Rupees(Rs.) | J12: No | K12: No | L12: No | M12: No | N12: 1 | O12: 0 | P12: 100 | Q12: 1 | R12: 2012 | S12: 9 | T12: 24 | U12: 41176 | V12: =Main[[#This Row],[Average_Cost_for_two]] * VLOOKUP(Main[[#This Row],[Currency]],'Currency'!A:B,2,FALSE) -> 1.2 | W12: =IF(Main[[#This Row],[Avg_Cost_USD]]<10,"Low", IF(Main[[#This Row],[Avg_Cost_USD]]<=30,"Medium","High")) -> Low
A13: 18424202 | B13: Famous Parantha and Poori Sabzi | C13: 1 | D13: New Delhi | E13: Vasundhara Enclave | F13: 77.308509 | G13: 28.589376 | H13: North Indian | I13: Indian Rupees(Rs.) | J13: No | K13: No | L13: No | M13: No | N13: 1 | O13: 0 | P13: 50 | Q13: 1 | R13: 2014 | S13: 9 | T13: 20 | U13: 41902 | V13: =Main[[#This Row],[Average_Cost_for_two]] * VLOOKUP(Main[[#This Row],[Currency]],'Currency'!A:B,2,FALSE) -> 0.6 | W13: =IF(Main[[#This Row],[Avg_Cost_USD]]<10,"Low", IF(Main[[#This Row],[Avg_Cost_USD]]<=30,"Medium","High")) -> Low
... A8655: 17334679 | B8655: Azteca | C8655: 216 | D8655: Davenport | E8655: Davenport | F8655: -90.5683 | G8655: 41.5699 | H8655: Mexican | I8655: Dollar($) | J8655: No | K8655: No | L8655: No | M8655: No | N8655: 1 | O8655: 167 | P8655: 0 | Q8655: 4.3 | R8655: 2015 | S8655: 9 | T8655: 28 | U8655: 42275 | V8655: =Main[[#This Row],[Average_Cost_for_two]] * VLOOKUP(Main[[#This Row],[Currency]],'Currency'!A:B,2,FALSE) -> 0 | W8655: =IF(Main[[#This Row],[Avg_Cost_USD]]<10,"Low", IF(Main[[#This Row],[Avg_Cost_USD]]<=30,"Medium","High")) -> Low
A8656: 17606621 | B8656: HI Lite Bar & Lounge | C8656: 216 | D8656: Miller | E8656: Miller | F8656: -98.9891 | G8656: 44.5158 | I8656: Dollar($) | J8656: No | K8656: No | L8656: No | M8656: No | N8656: 1 | O8656: 11 | P8656: 0 | Q8656: 3.4 | R8656: 2013 | S8656: 9 | T8656: 9 | U8656: 41526 | V8656: =Main[[#This Row],[Average_Cost_for_two]] * VLOOKUP(Main[[#This Row],[Currency]],'Currency'!A:B,2,FALSE) -> 0 | W8656: =IF(Main[[#This Row],[Avg_Cost_USD]]<10,"Low", IF(Main[[#This Row],[Avg_Cost_USD]]<=30,"Medium","High")) -> Low
A8657: 17582627 | B8657: Senor Iguanas | C8657: 216 | D8657: Pocatello | E8657: Pocatello | F8657: -112.4433 | G8657: 42.8942 | H8657: Mexican | I8657: Dollar($) | J8657: No | K8657: No | L8657: No | M8657: No | N8657: 1 | O8657: 108 | P8657: 0 | Q8657: 3.6 | R8657: 2017 | S8657: 9 | T8657: 1 | U8657: 42979 | V8657: =Main[[#This Row],[Average_Cost_for_two]] * VLOOKUP(Main[[#This Row],[Currency]],'Currency'!A:B,2,FALSE) -> 0 | W8657: =IF(Main[[#This Row],[Avg_Cost_USD]]<10,"Low", IF(Main[[#This Row],[Avg_Cost_USD]]<=30,"Medium","High")) -> Low
A8658: 2148 | B8658: 56 Ristorante Italiano | C8658: 1 | D8658: Gurgaon | E8658: Golf Course Road | F8658: 77.101996 | G8658: 28.440092 | H8658: Italian | I8658: Indian Rupees(Rs.) | J8658: Yes | K8658: Yes | L8658: No | M8658: No | N8658: 4 | O8658: 416 | P8658: 2200 | Q8658: 3.7 | R8658: 2010 | S8658: 1 | T8658: 9 | U8658: 40187 | V8658: =Main[[#This Row],[Average_Cost_for_two]] * VLOOKUP(Main[[#This Row],[Currency]],'Currency'!A:B,2,FALSE) -> 26.4 | W8658: =IF(Main[[#This Row],[Avg_Cost_USD]]<10,"Low", IF(Main[[#This Row],[Avg_Cost_USD]]<=30,"Medium","High")) -> Medium
A8659: 18317498 | B8659: The Butler & The Chef - Jaypee Greens | C8659: 1 | D8659: Noida | E8659: Jaypee Greens, Greater Noida, Noida | F8659: 77.521526 | G8659: 28.464167 | H8659: Finger Food | I8659: Indian Rupees(Rs.) | J8659: Yes | K8659: No | L8659: No | M8659: No | N8659: 4 | O8659: 1 | P8659: 2200 | Q8659: 1 | R8659: 2016 | S8659: 4 | T8659: 6 | U8659: 42466 | V8659: =Main[[#This Row],[Average_Cost_for_two]] * VLOOKUP(Main[[#This Row],[Currency]],'Currency'!A:B,2,FALSE) -> 26.4 | W8659: =IF(Main[[#This Row],[Avg_Cost_USD]]<10,"Low", IF(Main[[#This Row],[Avg_Cost_USD]]<=30,"Medium","High")) -> Medium
A8660: 3226 | B8660: Flluid - Mosaic Hotels | C8660: 1 | D8660: Noida | E8660: Mosaic Hotels, Sector 18, Noida | F8660: 77.325545 | G8660: 28.57102 | H8660: Continental, North Indian, Mexican | I8660: Indian Rupees(Rs.) | J8660: Yes | K8660: No | L8660: No | M8660: No | N8660: 4 | O8660: 135 | P8660: 2200 | Q8660: 3.2 | R8660: 2015 | S8660: 9 | T8660: 10 | U8660: 42257 | V8660: =Main[[#This Row],[Average_Cost_for_two]] * VLOOKUP(Main[[#This Row],[Currency]],'Currency'!A:B,2,FALSE) -> 26.4 | W8660: =IF(Main[[#This Row],[Avg_Cost_USD]]<10,"Low", IF(Main[[#This Row],[Avg_Cost_USD]]<=30,"Medium","High")) -> Medium
A8661: 4248 | B8661: The Great Kabab Factory | C8661: 1 | D8661: Noida | E8661: Sector 18 | F8661: 77.32181 | G8661: 28.572104 | H8661: North Indian, Mughlai | I8661: Indian Rupees(Rs.) | J8661: Yes | K8661: No | L8661: No | M8661: No | N8661: 4 | O8661: 540 | P8661: 2200 | Q8661: 3.5 | R8661: 2018 | S8661: 1 | T8661: 26 | U8661: 43126 | V8661: =Main[[#This Row],[Average_Cost_for_two]] * VLOOKUP(Main[[#This Row],[Currency]],'Currency'!A:B,2,FALSE) -> 26.4 | W8661: =IF(Main[[#This Row],[Avg_Cost_USD]]<10,"Low", IF(Main[[#This Row],[Avg_Cost_USD]]<=30,"Medium","High")) -> Medium
A8662: 17582524 | B8662: Butterburrs | C8662: 216 | D8662: Pocatello | E8662: Pocatello | F8662: -112.4516 | G8662: 42.8919 | H8662: American, Breakfast | I8662: Dollar($) | J8662: No | K8662: No | L8662: No | M8662: No | N8662: 3 | O8662: 121 | P8662: 30 | Q8662: 3.6 | R8662: 2016 | S8662: 7 | T8662: 25 | U8662: 42576 | V8662: =Main[[#This Row],[Average_Cost_for_two]] * VLOOKUP(Main[[#This Row],[Currency]],'Currency'!A:B,2,FALSE) -> 30 | W8662: =IF(Main[[#This Row],[Avg_Cost_USD]]<10,"Low", IF(Main[[#This Row],[Avg_Cost_USD]]<=30,"Medium","High")) -> Medium
A8663: 17144991 | B8663: Coconuts Fish Cafe | C8663: 216 | D8663: Rest of Hawaii | E8663: Kihei | F8663: -156.45528 | G8663: 20.748838 | H8663: Seafood | I8663: Dollar($) | J8663: No | K8663: No | L8663: No | M8663: No | N8663: 3 | O8663: 487 | P8663: 30 | Q8663: 4.5 | R8663: 2010 | S8663: 7 | T8663: 24 | U8663: 40383 | V8663: =Main[[#This Row],[Average_Cost_for_two]] * VLOOKUP(Main[[#This Row],[Currency]],'Currency'!A:B,2,FALSE) -> 30 | W8663: =IF(Main[[#This Row],[Avg_Cost_USD]]<10,"Low", IF(Main[[#This Row],[Avg_Cost_USD]]<=30,"Medium","High")) -> Medium
A8664: 121120 | B8664: Virgin Courtyard | C8664: 1 | D8664: Chandigarh | E8664: Sector 7 | F8664: 76.79762 | G8664: 30.73348 | H8664: Italian | I8664: Indian Rupees(Rs.) | J8664: No | K8664: No | L8664: No | M8664: No | N8664: 4 | O8664: 817 | P8664: 2200 | Q8664: 4.4 | R8664: 2010 | S8664: 6 | T8664: 11 | U8664: 40340 | V8664: =Main[[#This Row],[Average_Cost_for_two]] * VLOOKUP(Main[[#This Row],[Currency]],'Currency'!A:B,2,FALSE) -> 26.4 | W8664: =IF(Main[[#This Row],[Avg_Cost_USD]]<10,"Low", IF(Main[[#This Row],[Avg_Cost_USD]]<=30,"Medium","High")) -> Medium
A8665: 306581 | B8665: The Hungry Monkey | C8665: 1 | D8665: New Delhi | E8665: Safdarjung | F8665: 77.196097 | G8665: 28.559007 | H8665: European, Italian | I8665: Indian Rupees(Rs.) | J8665: Yes | K8665: No | L8665: No | M8665: No | N8665: 4 | O8665: 622 | P8665: 2300 | Q8665: 3.7 | R8665: 2010 | S8665: 11 | T8665: 8 | U8665: 40490 | V8665: =Main[[#This Row],[Average_Cost_for_two]] * VLOOKUP(Main[[#This Row],[Currency]],'Currency'!A:B,2,FALSE) -> 27.6 | W8665: =IF(Main[[#This Row],[Avg_Cost_USD]]<10,"Low", IF(Main[[#This Row],[Avg_Cost_USD]]<=30,"Medium","High")) -> Medium
A8666: 308016 | B8666: Sutra Gastropub | C8666: 1 | D8666: Gurgaon | E8666: Cyber Hub, DLF Cyber City | F8666: 77.088328 | G8666: 28.494815 | H8666: Mediterranean, European, American, North Indian | I8666: Indian Rupees(Rs.) | J8666: No | K8666: No | L8666: No | M8666: No | N8666: 4 | O8666: 1046 | P8666: 2300 | Q8666: 3.8 | R8666: 2011 | S8666: 10 | T8666: 17 | U8666: 40833 | V8666: =Main[[#This Row],[Average_Cost_for_two]] * VLOOKUP(Main[[#This Row],[Currency]],'Currency'!A:B,2,FALSE) -> 27.6 | W8666: =IF(Main[[#This Row],[Avg_Cost_USD]]<10,"Low", IF(Main[[#This Row],[Avg_Cost_USD]]<=30,"Medium","High")) -> Medium
A8667: 102215 | B8667: Monarch Restaurant - Holiday Inn Jaipur City Centre | C8667: 1 | D8667: Jaipur | E8667: Holiday Inn Jaipur City Centre, Bais Godam | F8667: 75.793007 | G8667: 26.90294 | H8667: North Indian, Chinese, Continental, Rajasthani | I8667: Indian Rupees(Rs.) | J8667: No | K8667: No | L8667: No | M8667: No | N8667: 4 | O8667: 420 | P8667: 2300 | Q8667: 4.5 | R8667: 2013 | S8667: 5 | T8667: 6 | U8667: 41400 | V8667: =Main[[#This Row],[Average_Cost_for_two]] * VLOOKUP(Main[[#This Row],[Currency]],'Currency'!A:B,2,FALSE) -> 27.6 | W8667: =IF(Main[[#This Row],[Avg_Cost_USD]]<10,"Low", IF(Main[[#This Row],[Avg_Cost_USD]]<=30,"Medium","High")) -> Medium
A8668: 18175334 | B8668: TFK - The Flaming Kick | C8668: 1 | D8668: Noida | E8668: Sector 18 | F8668: 77.322369 | G8668: 28.56955 | H8668: North Indian, Asian, Continental | I8668: Indian Rupees(Rs.) | J8668: Yes | K8668: Yes | L8668: No | M8668: No | N8668: 4 | O8668: 214 | P8668: 2350 | Q8668: 3.5 | R8668: 2015 | S8668: 5 | T8668: 9 | U8668: 42133 | V8668: =Main[[#This Row],[Average_Cost_for_two]] * VLOOKUP(Main[[#This Row],[Currency]],'Currency'!A:B,2,FALSE) -> 28.2 | W8668: =IF(Main[[#This Row],[Avg_Cost_USD]]<10,"Low", IF(Main[[#This Row],[Avg_Cost_USD]]<=30,"Medium","High")) -> Medium
A8669: 17284211 | B8669: Pearly's Famous Country Cookng | C8669: 216 | D8669: Albany | E8669: Albany | F8669: -84.1759 | G8669: 31.5882 | I8669: Dollar($) | J8669: No | K8669: No | L8669: No | M8669: No | N8669: 1 | O8669: 36 | P8669: 0 | Q8669: 3.4 | R8669: 2011 | S8669: 4 | T8669: 25 | U8669: 40658 | V8669: =Main[[#This Row],[Average_Cost_for_two]] * VLOOKUP(Main[[#This Row],[Currency]],'Currency'!A:B,2,FALSE) -> 0 | W8669: =IF(Main[[#This Row],[Avg_Cost_USD]]<10,"Low", IF(Main[[#This Row],[Avg_Cost_USD]]<=30,"Medium","High")) -> Low
A8670: 17064266 | B8670: Hawkers Asian Street Fare | C8670: 216 | D8670: Orlando | E8670: Mills 50 | F8670: -81.364347 | G8670: 28.560505 | H8670: Asian, Thai | I8670: Dollar($) | J8670: No | K8670: No | L8670: No | M8670: No | N8670: 3 | O8670: 1293 | P8670: 35 | Q8670: 4.6 | R8670: 2017 | S8670: 4 | T8670: 14 | U8670: 42839 | V8670: =Main[[#This Row],[Average_Cost_for_two]] * VLOOKUP(Main[[#This Row],[Currency]],'Currency'!A:B,2,FALSE) -> 35 | W8670: =IF(Main[[#This Row],[Avg_Cost_USD]]<10,"Low", IF(Main[[#This Row],[Avg_Cost_USD]]<=30,"Medium","High")) -> High
A8671: 307330 | B8671: Moonshine Cafe & Bar | C8671: 1 | D8671: New Delhi | E8671: Hauz Khas Village | F8671: 77.194159 | G8671: 28.554131 | H8671: Continental, Italian | I8671: Indian Rupees(Rs.) | J8671: No | K8671: No | L8671: No | M8671: No | N8671: 4 | O8671: 884 | P8671: 2400 | Q8671: 3.5 | R8671: 2014 | S8671: 3 | T8671: 5 | U8671: 41703 | V8671: =Main[[#This Row],[Average_Cost_for_two]] * VLOOKUP(Main[[#This Row],[Currency]],'Currency'!A:B,2,FALSE) -> 28.8 | W8671: =IF(Main[[#This Row],[Avg_Cost_USD]]<10,"Low", IF(Main[[#This Row],[Avg_Cost_USD]]<=30,"Medium","High")) -> Medium
A8672: 17061205 | B8672: Yellow Dog Eats | C8672: 216 | D8672: Orlando | E8672: Windermere | F8672: -81.522987 | G8672: 28.527592 | H8672: American, BBQ, Sandwich | I8672: Dollar($) | J8672: No | K8672: No | L8672: No | M8672: No | N8672: 3 | O8672: 1252 | P8672: 35 | Q8672: 4.9 | R8672: 2012 | S8672: 4 | T8672: 5 | U8672: 41004 | V8672: =Main[[#This Row],[Average_Cost_for_two]] * VLOOKUP(Main[[#This Row],[Currency]],'Currency'!A:B,2,FALSE) -> 35 | W8672: =IF(Main[[#This Row],[Avg_Cost_USD]]<10,"Low", IF(Main[[#This Row],[Avg_Cost_USD]]<=30,"Medium","High")) -> High
A8673: 17330155 | B8673: Deorio's | C8673: 216 | D8673: Columbus | E8673: Columbus | F8673: -84.9427 | G8673: 32.481 | H8673: Italian, Pizza | I8673: Dollar($) | J8673: No | K8673: No | L8673: No | M8673: No | N8673: 1 | O8673: 170 | P8673: 0 | Q8673: 4 | R8673: 2012 | S8673: 3 | T8673: 26 | U8673: 40994 | V8673: =Main[[#This Row],[Average_Cost_for_two]] * VLOOKUP(Main[[#This Row],[Currency]],'Currency'!A:B,2,FALSE) -> 0 | W8673: =IF(Main[[#This Row],[Avg_Cost_USD]]<10,"Low", IF(Main[[#This Row],[Avg_Cost_USD]]<=30,"Medium","High")) -> Low
A8674: 17582499 | B8674: Royal Hotel | C8674: 216 | D8674: Pocatello | E8674: Lava Hot Springs | F8674: -112.0127 | G8674: 42.6192 | H8674: Pizza, Bar Food | I8674: Dollar($) | J8674: No | K8674: No | L8674: No | M8674: No | N8674: 1 | O8674: 59 | P8674: 0 | Q8674: 3.6 | R8674: 2017 | S8674: 3 | T8674: 15 | U8674: 42809 | V8674: =Main[[#This Row],[Average_Cost_for_two]] * VLOOKUP(Main[[#This Row],[Currency]],'Currency'!A:B,2,FALSE) -> 0 | W8674: =IF(Main[[#This Row],[Avg_Cost_USD]]<10,"Low", IF(Main[[#This Row],[Avg_Cost_USD]]<=30,"Medium","High")) -> Low
A8675: 18359296 | B8675: Liquid | C8675: 1 | D8675: New Delhi | E8675: Prashant Vihar | F8675: 77.137506 | G8675: 28.71276 | H8675: North Indian, Mughlai, Chinese | I8675: Indian Rupees(Rs.) | J8675: Yes | K8675: No | L8675: No | M8675: No | N8675: 4 | O8675: 11 | P8675: 2400 | Q8675: 3.2 | R8675: 2011 | S8675: 12 | T8675: 2 | U8675: 40879 | V8675: =Main[[#This Row],[Average_Cost_for_two]] * VLOOKUP(Main[[#This Row],[Currency]],'Currency'!A:B,2,FALSE) -> 28.8 | W8675: =IF(Main[[#This Row],[Avg_Cost_USD]]<10,"Low", IF(Main[[#This Row],[Avg_Cost_USD]]<=30,"Medium","High")) -> Medium
A8676: 929 | B8676: Pebble Street | C8676: 1 | D8676: New Delhi | E8676: Community Centre, New Friends Colony | F8676: 77.268938 | G8676: 28.562538 | H8676: Italian, Tex-Mex, Continental, North Indian | I8676: Indian Rupees(Rs.) | J8676: Yes | K8676: Yes | L8676: No | M8676: No | N8676: 4 | O8676: 886 | P8676: 2400 | Q8676: 3.9 | R8676: 2018 | S8676: 10 | T8676: 8 | U8676: 43381 | V8676: =Main[[#This Row],[Average_Cost_for_two]] * VLOOKUP(Main[[#This Row],[Currency]],'Currency'!A:B,2,FALSE) -> 28.8 | W8676: =IF(Main[[#This Row],[Avg_Cost_USD]]<10,"Low", IF(Main[[#This Row],[Avg_Cost_USD]]<=30,"Medium","High")) -> Medium
A8677: 17057397 | B8677: 'Ohana | C8677: 216 | D8677: Orlando | E8677: Disney World Area | F8677: -81.585226 | G8677: 28.405437 | H8677: Hawaiian | I8677: Dollar($) | J8677: No | K8677: No | L8677: No | M8677: No | N8677: 3 | O8677: 1151 | P8677: 45 | Q8677: 4.5 | R8677: 2016 | S8677: 2 | T8677: 15 | U8677: 42415 | V8677: =Main[[#This Row],[Average_Cost_for_two]] * VLOOKUP(Main[[#This Row],[Currency]],'Currency'!A:B,2,FALSE) -> 45 | W8677: =IF(Main[[#This Row],[Avg_Cost_USD]]<10,"Low", IF(Main[[#This Row],[Avg_Cost_USD]]<=30,"Medium","High")) -> High
A8678: 3393 | B8678: Parikrama - The Revolving Restaurant | C8678: 1 | D8678: New Delhi | E8678: Connaught Place | F8678: 77.222638 | G8678: 28.628453 | H8678: North Indian, Chinese, Mughlai | I8678: Indian Rupees(Rs.) | J8678: No | K8678: No | L8678: No | M8678: No | N8678: 4 | O8678: 2689 | P8678: 2400 | Q8678: 3.8 | R8678: 2014 | S8678: 7 | T8678: 8 | U8678: 41828 | V8678: =Main[[#This Row],[Average_Cost_for_two]] * VLOOKUP(Main[[#This Row],[Currency]],'Currency'!A:B,2,FALSE) -> 28.8 | W8678: =IF(Main[[#This Row],[Avg_Cost_USD]]<10,"Low", IF(Main[[#This Row],[Avg_Cost_USD]]<=30,"Medium","High")) -> Medium
A8679: 17284302 | B8679: El Vaquero Mexican Restaurant | C8679: 216 | D8679: Albany | E8679: Albany | F8679: -84.2194 | G8679: 31.6158 | H8679: Mexican | I8679: Dollar($) | J8679: No | K8679: No | L8679: No | M8679: No | N8679: 1 | O8679: 45 | P8679: 0 | Q8679: 3.4 | R8679: 2016 | S8679: 1 | T8679: 23 | U8679: 42392 | V8679: =Main[[#This Row],[Average_Cost_for_two]] * VLOOKUP(Main[[#This Row],[Currency]],'Currency'!A:B,2,FALSE) -> 0 | W8679: =IF(Main[[#This Row],[Avg_Cost_USD]]<10,"Low", IF(Main[[#This Row],[Avg_Cost_USD]]<=30,"Medium","High")) -> Low
A8680: 3288 | B8680: Shanghai Bar & Lounge - The Bristol Hotel | C8680: 1 | D8680: Gurgaon | E8680: The Bristol Hotel, DLF Phase 1 | F8680: 77.09232 | G8680: 28.479998 | H8680: Finger Food | I8680: Indian Rupees(Rs.) | J8680: Yes | K8680: No | L8680: No | M8680: No | N8680: 4 | O8680: 17 | P8680: 2400 | Q8680: 3 | R8680: 2017 | S8680: 10 | T8680: 26 | U8680: 43034 | V8680: =Main[[#This Row],[Average_Cost_for_two]] * VLOOKUP(Main[[#This Row],[Currency]],'Currency'!A:B,2,FALSE) -> 28.8 | W8680: =IF(Main[[#This Row],[Avg_Cost_USD]]<10,"Low", IF(Main[[#This Row],[Avg_Cost_USD]]<=30,"Medium","High")) -> Medium
A8681: 3237 | B8681: Club Ice Cube | C8681: 1 | D8681: Noida | E8681: The Great India Place, Sector 38 | F8681: 77.326475 | G8681: 28.568067 | H8681: North Indian, Continental, Chinese | I8681: Indian Rupees(Rs.) | J8681: Yes | K8681: No | L8681: No | M8681: No | N8681: 4 | O8681: 230 | P8681: 2400 | Q8681: 2 | R8681: 2011 | S8681: 4 | T8681: 16 | U8681: 40649 | V8681: =Main[[#This Row],[Average_Cost_for_two]] * VLOOKUP(Main[[#This Row],[Currency]],'Currency'!A:B,2,FALSE) -> 28.8 | W8681: =IF(Main[[#This Row],[Avg_Cost_USD]]<10,"Low", IF(Main[[#This Row],[Avg_Cost_USD]]<=30,"Medium","High")) -> Medium
...

Sheet Currency
A1: Currency | B1: USD Rate
A2: Indian Rupees(Rs.) | B2: 0.012
A3: Dollar($) | B3: 1
A4: Pounds(Œ£) | B4: 1.24
A5: NewZealand($) | B5: 0.6
A6: Emirati Diram(AED) | B6: 0.27
A7: Brazilian Real(R$) | B7: 0.2
A8: Turkish Lira(TL) | B8: 0.05
A9: Qatari Rial(QR) | B9: 0.27
A10: Rand(R) | B10: 0.051
A11: Botswana Pula(P) | B11: 0.073
A12: Sri Lankan Rupee(LKR) | B12: 0.0034
A13: Indonesian Rupiah(IDR) | B13: 6.7e-05

Sheet Calendar1
A1: Date | B1: Year | C1: MonthNo | D1: MonthFullName | E1: Quarter | F1: YearMonth | G1: WeekdayNo | H1: WeekdayName | I1: FinancialMonth | J1: FinancialQuarter
A2: =MIN(Main[Date]) -> 40179 | B2: =YEAR(A2) -> 2010 | C2: =MONTH(A2) -> 1 | D2: =TEXT(A2,"mmmm") -> January | E2: ="Q"&ROUNDUP(MONTH(A2)/3,0) -> Q1 | F2: =TEXT(A2,"yyyy-mmm") -> 2010-Jan | G2: =WEEKDAY(A2) -> 6 | H2: =TEXT(A2,"dddd") -> Friday | I2: ="FM"&IF(MONTH(A2)>=4,MONTH(A2)-3,MONTH(A2)+9) -> FM10 | J2: ="FQ-"&ROUNDUP(IF(MONTH(A2)>=4,MONTH(A2)-3,MONTH(A2)+9)/3,0) -> FQ-4
A3: =A2+1 -> 40180 | B3: =YEAR(A3) -> 2010 | C3: =MONTH(A3) -> 1 | D3: =TEXT(A3,"mmmm") -> January | E3: ="Q"&ROUNDUP(MONTH(A3)/3,0) -> Q1 | F3: =TEXT(A3,"yyyy-mmm") -> 2010-Jan | G3: =WEEKDAY(A3) -> 7 | H3: =TEXT(A3,"dddd") -> Saturday | I3: ="FM"&IF(MONTH(A3)>=4,MONTH(A3)-3,MONTH(A3)+9) -> FM10 | J3: ="FQ-"&ROUNDUP(IF(MONTH(A3)>=4,MONTH(A3)-3,MONTH(A3)+9)/3,0) -> FQ-4
A4: =A3+1 -> 40181 | B4: =YEAR(A4) -> 2010 | C4: =MONTH(A4) -> 1 | D4: =TEXT(A4,"mmmm") -> January | E4: ="Q"&ROUNDUP(MONTH(A4)/3,0) -> Q1 | F4: =TEXT(A4,"yyyy-mmm") -> 2010-Jan | G4: =WEEKDAY(A4) -> 1 | H4: =TEXT(A4,"dddd") -> Sunday | I4: ="FM"&IF(MONTH(A4)>=4,MONTH(A4)-3,MONTH(A4)+9) -> FM10 | J4: ="FQ-"&ROUNDUP(IF(MONTH(A4)>=4,MONTH(A4)-3,MONTH(A4)+9)/3,0) -> FQ-4
A5: =A4+1 -> 40182 | B5: =YEAR(A5) -> 2010 | C5: =MONTH(A5) -> 1 | D5: =TEXT(A5,"mmmm") -> January | E5: ="Q"&ROUNDUP(MONTH(A5)/3,0) -> Q1 | F5: =TEXT(A5,"yyyy-mmm") -> 2010-Jan | G5: =WEEKDAY(A5) -> 2 | H5: =TEXT(A5,"dddd") -> Monday | I5: ="FM"&IF(MONTH(A5)>=4,MONTH(A5)-3,MONTH(A5)+9) -> FM10 | J5: ="FQ-"&ROUNDUP(IF(MONTH(A5)>=4,MONTH(A5)-3,MONTH(A5)+9)/3,0) -> FQ-4
A6: =A5+1 -> 40183 | B6: =YEAR(A6) -> 2010 | C6: =MONTH(A6) -> 1 | D6: =TEXT(A6,"mmmm") -> January | E6: ="Q"&ROUNDUP(MONTH(A6)/3,0) -> Q1 | F6: =TEXT(A6,"yyyy-mmm") -> 2010-Jan | G6: =WEEKDAY(A6) -> 3 | H6: =TEXT(A6,"dddd") -> Tuesday | I6: ="FM"&IF(MONTH(A6)>=4,MONTH(A6)-3,MONTH(A6)+9) -> FM10 | J6: ="FQ-"&ROUNDUP(IF(MONTH(A6)>=4,MONTH(A6)-3,MONTH(A6)+9)/3,0) -> FQ-4
A7: =A6+1 -> 40184 | B7: =YEAR(A7) -> 2010 | C7: =MONTH(A7) -> 1 | D7: =TEXT(A7,"mmmm") -> January | E7: ="Q"&ROUNDUP(MONTH(A7)/3,0) -> Q1 | F7: =TEXT(A7,"yyyy-mmm") -> 2010-Jan | G7: =WEEKDAY(A7) -> 4 | H7: =TEXT(A7,"dddd") -> Wednesday | I7: ="FM"&IF(MONTH(A7)>=4,MONTH(A7)-3,MONTH(A7)+9) -> FM10 | J7: ="FQ-"&ROUNDUP(IF(MONTH(A7)>=4,MONTH(A7)-3,MONTH(A7)+9)/3,0) -> FQ-4
A8: =A7+1 -> 40185 | B8: =YEAR(A8) -> 2010 | C8: =MONTH(A8) -> 1 | D8: =TEXT(A8,"mmmm") -> January | E8: ="Q"&ROUNDUP(MONTH(A8)/3,0) -> Q1 | F8: =TEXT(A8,"yyyy-mmm") -> 2010-Jan | G8: =WEEKDAY(A8) -> 5 | H8: =TEXT(A8,"dddd") -> Thursday | I8: ="FM"&IF(MONTH(A8)>=4,MONTH(A8)-3,MONTH(A8)+9) -> FM10 | J8: ="FQ-"&ROUNDUP(IF(MONTH(A8)>=4,MONTH(A8)-3,MONTH(A8)+9)/3,0) -> FQ-4 | L8: Min Date | M8: =MIN(Main[Date]) -> 40179
A9: =A8+1 -> 40186 | B9: =YEAR(A9) -> 2010 | C9: =MONTH(A9) -> 1 | D9: =TEXT(A9,"mmmm") -> January | E9: ="Q"&ROUNDUP(MONTH(A9)/3,0) -> Q1 | F9: =TEXT(A9,"yyyy-mmm") -> 2010-Jan | G9: =WEEKDAY(A9) -> 6 | H9: =TEXT(A9,"dddd") -> Friday | I9: ="FM"&IF(MONTH(A9)>=4,MONTH(A9)-3,MONTH(A9)+9) -> FM10 | J9: ="FQ-"&ROUNDUP(IF(MONTH(A9)>=4,MONTH(A9)-3,MONTH(A9)+9)/3,0) -> FQ-4 | L9: Max Date | M9: =MAX(Main[Date]) -> 43462
A10: =A9+1 -> 40187 | B10: =YEAR(A10) -> 2010 | C10: =MONTH(A10) -> 1 | D10: =TEXT(A10,"mmmm") -> January | E10: ="Q"&ROUNDUP(MONTH(A10)/3,0) -> Q1 | F10: =TEXT(A10,"yyyy-mmm") -> 2010-Jan | G10: =WEEKDAY(A10) -> 7 | H10: =TEXT(A10,"dddd") -> Saturday | I10: ="FM"&IF(MONTH(A10)>=4,MONTH(A10)-3,MONTH(A10)+9) -> FM10 | J10: ="FQ-"&ROUNDUP(IF(MONTH(A10)>=4,MONTH(A10)-3,MONTH(A10)+9)/3,0) -> FQ-4
A11: =A10+1 -> 40188 | B11: =YEAR(A11) -> 2010 | C11: =MONTH(A11) -> 1 | D11: =TEXT(A11,"mmmm") -> January | E11: ="Q"&ROUNDUP(MONTH(A11)/3,0) -> Q1 | F11: =TEXT(A11,"yyyy-mmm") -> 2010-Jan | G11: =WEEKDAY(A11) -> 1 | H11: =TEXT(A11,"dddd") -> Sunday | I11: ="FM"&IF(MONTH(A11)>=4,MONTH(A11)-3,MONTH(A11)+9) -> FM10 | J11: ="FQ-"&ROUNDUP(IF(MONTH(A11)>=4,MONTH(A11)-3,MONTH(A11)+9)/3,0) -> FQ-4
A12: =A11+1 -> 40189 | B12: =YEAR(A12) -> 2010 | C12: =MONTH(A12) -> 1 | D12: =TEXT(A12,"mmmm") -> January | E12: ="Q"&ROUNDUP(MONTH(A12)/3,0) -> Q1 | F12: =TEXT(A12,"yyyy-mmm") -> 2010-Jan | G12: =WEEKDAY(A12) -> 2 | H12: =TEXT(A12,"dddd") -> Monday | I12: ="FM"&IF(MONTH(A12)>=4,MONTH(A12)-3,MONTH(A12)+9) -> FM10 | J12: ="FQ-"&ROUNDUP(IF(MONTH(A12)>=4,MONTH(A12)-3,MONTH(A12)+9)/3,0) -> FQ-4
A13: =A12+1 -> 40190 | B13: =YEAR(A13) -> 2010 | C13: =MONTH(A13) -> 1 | D13: =TEXT(A13,"mmmm") -> January | E13: ="Q"&ROUNDUP(MONTH(A13)/3,0) -> Q1 | F13: =TEXT(A13,"yyyy-mmm") -> 2010-Jan | G13: =WEEKDAY(A13) -> 3 | H13: =TEXT(A13,"dddd") -> Tuesday | I13: ="FM"&IF(MONTH(A13)>=4,MONTH(A13)-3,MONTH(A13)+9) -> FM10 | J13: ="FQ-"&ROUNDUP(IF(MONTH(A13)>=4,MONTH(A13)-3,MONTH(A13)+9)/3,0) -> FQ-4
A14: =A13+1 -> 40191 | B14: =YEAR(A14) -> 2010 | C14: =MONTH(A14) -> 1 | D14: =TEXT(A14,"mmmm") -> January | E14: ="Q"&ROUNDUP(MONTH(A14)/3,0) -> Q1 | F14: =TEXT(A14,"yyyy-mmm") -> 2010-Jan | G14: =WEEKDAY(A14) -> 4 | H14: =TEXT(A14,"dddd") -> Wednesday | I14: ="FM"&IF(MONTH(A14)>=4,MONTH(A14)-3,MONTH(A14)+9) -> FM10 | J14: ="FQ-"&ROUNDUP(IF(MONTH(A14)>=4,MONTH(A14)-3,MONTH(A14)+9)/3,0) -> FQ-4
A15: =A14+1 -> 40192 | B15: =YEAR(A15) -> 2010 | C15: =MONTH(A15) -> 1 | D15: =TEXT(A15,"mmmm") -> January | E15: ="Q"&ROUNDUP(MONTH(A15)/3,0) -> Q1 | F15: =TEXT(A15,"yyyy-mmm") -> 2010-Jan | G15: =WEEKDAY(A15) -> 5 | H15: =TEXT(A15,"dddd") -> Thursday | I15: ="FM"&IF(MONTH(A15)>=4,MONTH(A15)-3,MONTH(A15)+9) -> FM10 | J15: ="FQ-"&ROUNDUP(IF(MONTH(A15)>=4,MONTH(A15)-3,MONTH(A15)+9)/3,0) -> FQ-4
A16: =A15+1 -> 40193 | B16: =YEAR(A16) -> 2010 | C16: =MONTH(A16) -> 1 | D16: =TEXT(A16,"mmmm") -> January | E16: ="Q"&ROUNDUP(MONTH(A16)/3,0) -> Q1 | F16: =TEXT(A16,"yyyy-mmm") -> 2010-Jan | G16: =WEEKDAY(A16) -> 6 | H16: =TEXT(A16,"dddd") -> Friday | I16: ="FM"&IF(MONTH(A16)>=4,MONTH(A16)-3,MONTH(A16)+9) -> FM10 | J16: ="FQ-"&ROUNDUP(IF(MONTH(A16)>=4,MONTH(A16)-3,MONTH(A16)+9)/3,0) -> FQ-4
A17: =A16+1 -> 40194 | B17: =YEAR(A17) -> 2010 | C17: =MONTH(A17) -> 1 | D17: =TEXT(A17,"mmmm") -> January | E17: ="Q"&ROUNDUP(MONTH(A17)/3,0) -> Q1 | F17: =TEXT(A17,"yyyy-mmm") -> 2010-Jan | G17: =WEEKDAY(A17) -> 7 | H17: =TEXT(A17,"dddd") -> Saturday | I17: ="FM"&IF(MONTH(A17)>=4,MONTH(A17)-3,MONTH(A17)+9) -> FM10 | J17: ="FQ-"&ROUNDUP(IF(MONTH(A17)>=4,MONTH(A17)-3,MONTH(A17)+9)/3,0) -> FQ-4
A18: =A17+1 -> 40195 | B18: =YEAR(A18) -> 2010 | C18: =MONTH(A18) -> 1 | D18: =TEXT(A18,"mmmm") -> January | E18: ="Q"&ROUNDUP(MONTH(A18)/3,0) -> Q1 | F18: =TEXT(A18,"yyyy-mmm") -> 2010-Jan | G18: =WEEKDAY(A18) -> 1 | H18: =TEXT(A18,"dddd") -> Sunday | I18: ="FM"&IF(MONTH(A18)>=4,MONTH(A18)-3,MONTH(A18)+9) -> FM10 | J18: ="FQ-"&ROUNDUP(IF(MONTH(A18)>=4,MONTH(A18)-3,MONTH(A18)+9)/3,0) -> FQ-4
A19: =A18+1 -> 40196 | B19: =YEAR(A19) -> 2010 | C19: =MONTH(A19) -> 1 | D19: =TEXT(A19,"mmmm") -> January | E19: ="Q"&ROUNDUP(MONTH(A19)/3,0) -> Q1 | F19: =TEXT(A19,"yyyy-mmm") -> 2010-Jan | G19: =WEEKDAY(A19) -> 2 | H19: =TEXT(A19,"dddd") -> Monday | I19: ="FM"&IF(MONTH(A19)>=4,MONTH(A19)-3,MONTH(A19)+9) -> FM10 | J19: ="FQ-"&ROUNDUP(IF(MONTH(A19)>=4,MONTH(A19)-3,MONTH(A19)+9)/3,0) -> FQ-4
A20: =A19+1 -> 40197 | B20: =YEAR(A20) -> 2010 | C20: =MONTH(A20) -> 1 | D20: =TEXT(A20,"mmmm") -> January | E20: ="Q"&ROUNDUP(MONTH(A20)/3,0) -> Q1 | F20: =TEXT(A20,"yyyy-mmm") -> 2010-Jan | G20: =WEEKDAY(A20) -> 3 | H20: =TEXT(A20,"dddd") -> Tuesday | I20: ="FM"&IF(MONTH(A20)>=4,MONTH(A20)-3,MONTH(A20)+9) -> FM10 | J20: ="FQ-"&ROUNDUP(IF(MONTH(A20)>=4,MONTH(A20)-3,MONTH(A20)+9)/3,0) -> FQ-4
A21: =A20+1 -> 40198 | B21: =YEAR(A21) -> 2010 | C21: =MONTH(A21) -> 1 | D21: =TEXT(A21,"mmmm") -> January | E21: ="Q"&ROUNDUP(MONTH(A21)/3,0) -> Q1 | F21: =TEXT(A21,"yyyy-mmm") -> 2010-Jan | G21: =WEEKDAY(A21) -> 4 | H21: =TEXT(A21,"dddd") -> Wednesday | I21: ="FM"&IF(MONTH(A21)>=4,MONTH(A21)-3,MONTH(A21)+9) -> FM10 | J21: ="FQ-"&ROUNDUP(IF(MONTH(A21)>=4,MONTH(A21)-3,MONTH(A21)+9)/3,0) -> FQ-4
... A3285: =A3284+1 -> 43462 | B3285: =YEAR(A3285) -> 2018 | C3285: =MONTH(A3285) -> 12 | D3285: =TEXT(A3285,"mmmm") -> December | E3285: ="Q"&ROUNDUP(MONTH(A3285)/3,0) -> Q4 | F3285: =TEXT(A3285,"yyyy-mmm") -> 2018-Dec | G3285: =WEEKDAY(A3285) -> 6 | H3285: =TEXT(A3285,"dddd") -> Friday | I3285: ="FM"&IF(MONTH(A3285)>=4,MONTH(A3285)-3,MONTH(A3285)+9) -> FM9 | J3285: ="FQ-"&ROUNDUP(IF(MONTH(A3285)>=4,MONTH(A3285)-3,MONTH(A3285)+9)/3,0) -> FQ-3

Sheet Country
A1: CountryID | B1: Countryname
A2: 1 | B2: India
A3: 14 | B3: Australia
A4: 30 | B4: Brazil
A5: 37 | B5: Canada
A6: 94 | B6: Indonasia
A7: 148 | B7: New Zealand
A8: 162 | B8: Phillipines
A9: 166 | B9: Qatar
A10: 184 | B10: Singapore
A11: 189 | B11: South Africa
A12: 191 | B12: Sri lanka
A13: 208 | B13: Turkey
... A16: 216 | B16: United States

Sheet Q4
A1: Row Labels | B1: Count of RestaurantID
A2: Australia
A3: Armidale | B3: 1
A4: Balingup | B4: 1
A5: Beechworth | B5: 1
A6: Dicky Beach | B6: 1
A7: East Ballina | B7: 1
A8: Flaxton | B8: 1
A9: Forrest | B9: 1
A10: Hepburn Springs | B10: 2
A11: Huskisson | B11: 1
A12: Inverloch | B12: 1
A13: Lakes Entrance | B13: 1
A14: Lorn | B14: 1
... A25: Victor Harbor | B25: 1
A26: Brazil
A27: Brasí_lia | B27: 20
A28: Rio de Janeiro | B28: 20
A29: Sí£o Paulo | B29: 20
A30: Canada
A31: Chatham-Kent | B31: 1
A32: Consort | B32: 1
A33: Vineland Station | B33: 1
A34: Yorkton | B34: 1
A35: India
A36: Agra | B36: 20
A37: Ahmedabad | B37: 21
A38: Allahabad | B38: 20
A39: Amritsar | B39: 21
A40: Aurangabad | B40: 20
A41: Bangalore | B41: 20
A42: Bhopal | B42: 20
A43: Bhubaneshwar | B43: 21
A44: Chandigarh | B44: 18
A45: Chennai | B45: 20
A46: Coimbatore | B46: 20
A47: Dehradun | B47: 20
... A78: Vizag | B78: 20
A79: Indonasia
A80: Bandung | B80: 1
...

Sheet Q5
A3: Row Labels | B3: Count of RestaurantID
A4: 2010
A5: Q1
A6: February | B6: 77
A7: January | B7: 83
A8: March | B8: 90
A9: Q2
A10: April | B10: 91
A11: June | B11: 89
A12: May | B12: 77
A13: Q3
A14: August | B14: 97
A15: July | B15: 96
A16: September | B16: 90
A17: Q4
A18: December | B18: 91
A19: November | B19: 103
A20: October | B20: 96
A21: 2011
A22: Q1
A23: February | B23: 87
A24: January | B24: 76
A25: March | B25: 119
A26: Q2
A27: April | B27: 102
A28: June | B28: 90
A29: May | B29: 80
A30: Q3
A31: August | B31: 94
A32: July | B32: 107
A33: September | B33: 107
A34: Q4
A35: December | B35: 75
A36: November | B36: 76
A37: October | B37: 85
A38: 2012
A39: Q1
A40: February | B40: 69
A41: January | B41: 73
A42: March | B42: 87
...

Sheet Q6
A3: Row Labels | B3: Count of RestaurantID
A4: 1 | B4: 2148
A5: 1.8 | B5: 1
A6: 1.9 | B6: 2
A7: 2 | B7: 7
A8: 2.1 | B8: 15
A9: 2.2 | B9: 27
A10: 2.3 | B10: 47
A11: 2.4 | B11: 87
A12: 2.5 | B12: 110
A13: 2.6 | B13: 191
A14: 2.7 | B14: 250
A15: 2.8 | B15: 315
... A36: 4.9 | B36: 61
A37: Grand Total | B37: 9551

Sheet Q7
A3: Row Labels | B3: Count of RestaurantID
A4: High | B4: 461
A5: Low | B5: 7143
A6: Medium | B6: 1947
A7: Grand Total | B7: 9551

Sheet Q8
A3: Row Labels | B3: Count of RestaurantID
A4: No | B4: 0.87875615
A5: Yes | B5: 0.12124385
A6: Grand Total | B6: 1

Sheet Q9
A1: Row Labels | B1: Count of RestaurantID
A2: No | B2: 0.74337766
A3: Yes | B3: 0.25662234
A4: Grand Total | B4: 1

Sheet Sheet1
A1: Data returned for Count of RestaurantID, Australia - Hepburn Springs (First 1000 rows).
A3: Main[RestaurantID] | B3: Main[RestaurantName] | C3: Main[CountryCode] | D3: Main[City] | E3: Main[Locality] | F3: Main[Longitude] | G3: Main[Latitude] | H3: Main[Cuisines] | I3: Main[Currency] | J3: Main[Has_Table_booking] | K3: Main[Has_Online_delivery] | L3: Main[Is_delivering_now] | M3: Main[Switch_to_order_menu] | N3: Main[Price_range] | O3: Main[Votes] | P3: Main[Average_Cost_for_two] | Q3: Main[Rating] | R3: Main[Year Opening] | S3: Main[Month Opening] | T3: Main[Day Opening] | U3: Main[Date]
A4: 16604358 | B4: Blue Bean Love Cafe | C4: 14 | D4: Hepburn Springs | E4: Hepburn Springs | F4: 144.1387 | G4: -37.312327 | H4: Cafe, Coffee and Tea, Modern Australian | I4: Dollar($) | J4: No | K4: No | L4: No | M4: No | N4: 2 | O4: 192 | P4: 20 | Q4: 3.8 | R4: 2012 | S4: 8 | T4: 4 | U4: 41125
A5: 16604896 | B5: La Trattoria of Lavandula | C5: 14 | D5: Hepburn Springs | E5: Hepburn Springs | F5: 144.11006 | G5: -37.275494 | H5: Italian, Fusion, Cafe | I5: Dollar($) | J5: No | K5: No | L5: No | M5: No | N5: 1 | O5: 93 | P5: 7 | Q5: 3.8 | R5: 2013 | S5: 6 | T5: 13 | U5: 41438
